Traceback (most recent call last):
  File "/usr/share/miniconda3/envs/runenv/lib/python3.8/site-packages/jupyter_cache/executors/utils.py", line 51, in single_nb_execution
    executenb(
  File "/usr/share/miniconda3/envs/runenv/lib/python3.8/site-packages/nbclient/client.py", line 1082, in execute
    return NotebookClient(nb=nb, resources=resources, km=km, **kwargs).execute()
  File "/usr/share/miniconda3/envs/runenv/lib/python3.8/site-packages/nbclient/util.py", line 74, in wrapped
    return just_run(coro(*args, **kwargs))
  File "/usr/share/miniconda3/envs/runenv/lib/python3.8/site-packages/nbclient/util.py", line 53, in just_run
    return loop.run_until_complete(coro)
  File "/usr/share/miniconda3/envs/runenv/lib/python3.8/asyncio/base_events.py", line 616, in run_until_complete
    return future.result()
  File "/usr/share/miniconda3/envs/runenv/lib/python3.8/site-packages/nbclient/client.py", line 535, in async_execute
    await self.async_execute_cell(
  File "/usr/share/miniconda3/envs/runenv/lib/python3.8/site-packages/nbclient/client.py", line 827, in async_execute_cell
    self._check_raise_for_error(cell, exec_reply)
  File "/usr/share/miniconda3/envs/runenv/lib/python3.8/site-packages/nbclient/client.py", line 735, in _check_raise_for_error
    raise CellExecutionError.from_cell_and_msg(cell, exec_reply['content'])
nbclient.exceptions.CellExecutionError: An error occurred while executing the following cell:
------------------
add_contact("John", "Smith",
           phone="555 8765",
           email="john.smith@python.org")
------------------

[0;31m---------------------------------------------------------------------------[0m
[0;31mNameError[0m                                 Traceback (most recent call last)
[0;32m<ipython-input-24-9581700007e6>[0m in [0;36m<module>[0;34m[0m
[0;32m----> 1[0;31m add_contact("John", "Smith",
[0m[1;32m      2[0m            [0mphone[0m[0;34m=[0m[0;34m"555 8765"[0m[0;34m,[0m[0;34m[0m[0;34m[0m[0m
[1;32m      3[0m            email="john.smith@python.org")

[0;32m<ipython-input-23-5a2bcf0288b1>[0m in [0;36madd_contact[0;34m(kind, *args, **kwargs)[0m
[1;32m      2[0m     [0mprint[0m[0;34m([0m[0margs[0m[0;34m)[0m[0;34m[0m[0;34m[0m[0m
[1;32m      3[0m     [0mprint[0m[0;34m([0m[0;34m"-"[0m [0;34m*[0m [0;36m40[0m[0;34m)[0m[0;34m[0m[0;34m[0m[0m
[0;32m----> 4[0;31m     [0;32mfor[0m [0mkey[0m[0;34m,[0m [0mvalue[0m [0;32min[0m [0mkeywords[0m[0;34m.[0m[0mitems[0m[0;34m([0m[0;34m)[0m[0;34m:[0m[0;34m[0m[0;34m[0m[0m
[0m[1;32m      5[0m         [0mprint[0m[0;34m([0m[0mkey[0m[0;34m,[0m [0;34m":"[0m[0;34m,[0m [0mvalue[0m[0;34m)[0m[0;34m[0m[0;34m[0m[0m

[0;31mNameError[0m: name 'keywords' is not defined
NameError: name 'keywords' is not defined

